Workbook
Name assocfees: [1]Sheet2!$F:$F
Name construction: [1]Sheet2!$E:$E
Name garagetype: [1]Sheet2!$B:$B
Name rooftype: [1]Sheet2!$A:$A
Name smokedetector: [1]Sheet2!$D:$D
Name sprinklered: [1]Sheet2!$C:$C

Sheet General Info and Liability
A1: General Information | C1: Management Information
A2: Insured Name | B2: 821 Bay Street Homeowners Association, Inc. | C2: Management Company | D2: RowCal
A3: Effective Date | B3: 45894 | C3: Contact Name | D3: Rachael Clark//Deborah Maglasang
A4: Location Address | B4: 821 Bay St | C4: Address | D4: PO Box 421150
A5: Location City | B5: Santa Monica | C5: City | D5: Minneapolis
A6: Location State | B6: CA | C6: State | D6: MN
A7: Location Zip | B7: 90405 | C7: Zip | D7: 55442
A8: Association Type | B8: CONDO | C8: Phone | D8: (310) 776-5409
A9: Total Planned Units | B9: 15 | C9: Email | D9: Rachael.Clark@rowcal.com//Deborah Maglasang@rowcal.com
A10: Number of Completed Units | B10: 15 | C10: Self-Managed | D10: NO
A11: Association By-Laws Coverage/Insuring Agreement | B11: Single Entity | C11: Target Premium
A12: Need by Date | B12: 45863 | C12: Sum of Losses Past 4 years
A13: Property Information
A14: Number of Stories | B14: 3 | C14: Livable Square Footage | D14: 22200
A15: Number of Buildings | B15: 4 | C15: Parking Square Footage | D15: 6000
A16: Roof Type | B16: Flat | C16: Parking Type | D16: Partial Subterranean
A17: Building Valuation Type | B17: Replacement Cost | C17: Smoke Detectors | D17: Battery
A18: Building Replacement Cost | B18: 6661141 | C18: Sprinklered | D18: NO
A19: Blanket Outdoor Property | B19: ='Property Schedule'!F38 -> 140000 | C19: Year of Construction | D19: 1981
A20: Business Personal Property/Contents | B20: 10000 | C20: Construction Type | D20: Frame
A21: Total Insurable Value | B21: =SUM(B18:B19) -> 6801141 | C21: Cost per Square Foot | D21: =IF(AND(NOT(ISBLANK(B18)), NOT(ISBLANK(D14)), NOT(ISBLANK(D15))), $B$18/($D$14+$D$15), "$0") -> 236.21067
A22: Exposure Information
A23: Common Exposures | B23: Quantity | C23: Unit of Measure | D23: Misc. Notes
A24: Playgrounds | C24: Number | D24: EIN/Tax ID= 95-3901526
A25: Streets | C25: Miles | D25: Security cameras around premises
A26: Pools | C26: Number | D26: 50k prop deductible
A27: Spas | C27: Number
A28: Wader Pools | C28: Number
A29: Restroom Building | C29: Sq Ft
A30: Guardhouse | C30: Sq Ft
A31: Clubhouse | C31: Sq Ft
A32: Fitness Center | C32: Sq Ft
A33: Tennis Courts | C33: Number
A34: Basketball Courts | C34: Number
A35: Other Sport Courts | C35: Number
A36: Walking / Biking Trails | C36: Miles
A37: Lakes or Ponds | C37: Number
A38: Boat Docks and Slips | C38: Number
... A41: Commercial Exposure | C41: Sq Ft
A42: Other:
...

Sheet Property Schedule
A1: Common Exposures | C1: Quantity | D1: Unit of Measure | E1: Cost / Unit (Suggested) | F1: Replacement Cost | H1: Building # | I1: Address | J1: Unit #s (if applicable) | K1: Replacement Cost | L1: # of Units | M1: Livable Square Footage | N1: Garage Square Footage | O1: Commercial Sq Ft (if any) | P1: Building Class | Q1: Parking Type | R1: Roof Type | S1: Smoke Detectors | T1: Sprinklered | U1: Year of Construction | V1: Number of Stories | W1: Construction Type
A2: Playgrounds | C2: ='General Info and Liability'!B24 -> 0 | D2: Number | E2: 35000 | F2: =E2*C2 -> 0 | H2: =IF(OR('General Info and Liability'!$B$15=1,'General Info and Liability'!B15>1),1,"") -> 1 | K2: =IFERROR(IF(H2>0,'General Info and Liability'!$B$18/'General Info and Liability'!$B$10*$L2,""),"") -> 2220380.3 | L2: 5 | M2: =IFERROR(IF(H2>0,'General Info and Liability'!$D$14/'General Info and Liability'!$B$10*$L2,""),"") -> 7400 | N2: =IFERROR(IF(H2>0,'General Info and Liability'!$D$15/'General Info and Liability'!$B$10*$L2,""),"") -> 2000 | Q2: =IFERROR(IF(H2>0,'General Info and Liability'!$D$16,""),"") -> Partial Subterranean | R2: =IFERROR(IF(H2>0,'General Info and Liability'!$B$16,""),"") -> Flat | S2: =IFERROR(IF(H2>0,'General Info and Liability'!$D$17,""),"") -> Battery | T2: =IFERROR(IF(H2>0,'General Info and Liability'!$D$18,""),"") -> NO | U2: =IFERROR(IF(H2>0,'General Info and Liability'!$D$19,""),"") -> 1981 | V2: =IFERROR(IF(H2>0,'General Info and Liability'!$B$14,""),"") -> 3 | W2: =IFERROR(IF(H2>0,'General Info and Liability'!$D$20,""),"") -> Frame
A3: Streets | C3: ='General Info and Liability'!B25 -> 0 | D3: Miles | E3: 15000 | F3: =E3*C3 -> 0 | H3: =IFERROR(IF(H2+1<'General Info and Liability'!$B$15+1,'Property Schedule'!H2+1,""),"") -> 2 | K3: =IFERROR(IF($H2+1<'General Info and Liability'!$B$15+1,'General Info and Liability'!$B$18/'General Info and Liability'!$B$10*$L3,""),"") -> 1776304.3 | L3: 4 | M3: =IFERROR(IF($H2+1<'General Info and Liability'!$B$15+1,'General Info and Liability'!$D$14/'General Info and Liability'!$B$10*$L3,""),"") -> 5920 | N3: =IFERROR(IF($H2+1<'General Info and Liability'!$B$15+1,'General Info and Liability'!$D$15/'General Info and Liability'!$B$10*$L3,""),"") -> 1600 | Q3: =IFERROR(IF($H3+1>0,'General Info and Liability'!$D$16,""),"") -> Partial Subterranean | R3: =IFERROR(IF($H3+1>0,'General Info and Liability'!$B$16,""),"") -> Flat | S3: =IFERROR(IF($H2+1<'General Info and Liability'!$B$15+1,'General Info and Liability'!$D$17,""),"") -> Battery | T3: =IFERROR(IF($H2+1<'General Info and Liability'!$B$15+1,'General Info and Liability'!$D$18,""),"") -> NO | U3: =IFERROR(IF($H2+1<'General Info and Liability'!$B$15+1,'General Info and Liability'!$D$19,""),"") -> 1981 | V3: =IFERROR(IF($H2+1<'General Info and Liability'!$B$15+1,'General Info and Liability'!$B$14,""),"") -> 3 | W3: =IFERROR(IF($H2+1<'General Info and Liability'!$B$15+1,'General Info and Liability'!$D$20,""),"") -> Frame
A4: Pools | C4: ='General Info and Liability'!B26 -> 0 | D4: Number | E4: 65000 | F4: =E4*C4 -> 0 | H4: =IFERROR(IF(H3+1<'General Info and Liability'!$B$15+1,'Property Schedule'!H3+1,""),"") -> 3 | K4: =IFERROR(IF($H3+1<'General Info and Liability'!$B$15+1,'General Info and Liability'!$B$18/'General Info and Liability'!$B$10*$L4,""),"") -> 1332228.2 | L4: 3 | M4: =IFERROR(IF($H3+1<'General Info and Liability'!$B$15+1,'General Info and Liability'!$D$14/'General Info and Liability'!$B$10*$L4,""),"") -> 4440 | N4: =IFERROR(IF($H3+1<'General Info and Liability'!$B$15+1,'General Info and Liability'!$D$15/'General Info and Liability'!$B$10*$L4,""),"") -> 1200 | Q4: =IFERROR(IF($H4+1>0,'General Info and Liability'!$D$16,""),"") -> Partial Subterranean | R4: =IFERROR(IF($H4+1>0,'General Info and Liability'!$B$16,""),"") -> Flat | S4: =IFERROR(IF($H3+1<'General Info and Liability'!$B$15+1,'General Info and Liability'!$D$17,""),"") -> Battery | T4: =IFERROR(IF($H3+1<'General Info and Liability'!$B$15+1,'General Info and Liability'!$D$18,""),"") -> NO | U4: =IFERROR(IF($H3+1<'General Info and Liability'!$B$15+1,'General Info and Liability'!$D$19,""),"") -> 1981 | V4: =IFERROR(IF($H3+1<'General Info and Liability'!$B$15+1,'General Info and Liability'!$B$14,""),"") -> 3 | W4: =IFERROR(IF($H3+1<'General Info and Liability'!$B$15+1,'General Info and Liability'!$D$20,""),"") -> Frame
A5: Spas | C5: ='General Info and Liability'!B27 -> 0 | D5: Number | E5: 30000 | F5: =E5*C5 -> 0 | H5: =IFERROR(IF(H4+1<'General Info and Liability'!$B$15+1,'Property Schedule'!H4+1,""),"") -> 4 | K5: =IFERROR(IF($H4+1<'General Info and Liability'!$B$15+1,'General Info and Liability'!$B$18/'General Info and Liability'!$B$10*$L5,""),"") -> 1332228.2 | L5: 3 | M5: =IFERROR(IF($H4+1<'General Info and Liability'!$B$15+1,'General Info and Liability'!$D$14/'General Info and Liability'!$B$10*$L5,""),"") -> 4440 | N5: =IFERROR(IF($H4+1<'General Info and Liability'!$B$15+1,'General Info and Liability'!$D$15/'General Info and Liability'!$B$10*$L5,""),"") -> 1200 | Q5: =IFERROR(IF($H5+1>0,'General Info and Liability'!$D$16,""),"") -> Partial Subterranean | R5: =IFERROR(IF($H5+1>0,'General Info and Liability'!$B$16,""),"") -> Flat | S5: =IFERROR(IF($H4+1<'General Info and Liability'!$B$15+1,'General Info and Liability'!$D$17,""),"") -> Battery | T5: =IFERROR(IF($H4+1<'General Info and Liability'!$B$15+1,'General Info and Liability'!$D$18,""),"") -> NO | U5: =IFERROR(IF($H4+1<'General Info and Liability'!$B$15+1,'General Info and Liability'!$D$19,""),"") -> 1981 | V5: =IFERROR(IF($H4+1<'General Info and Liability'!$B$15+1,'General Info and Liability'!$B$14,""),"") -> 3 | W5: =IFERROR(IF($H4+1<'General Info and Liability'!$B$15+1,'General Info and Liability'!$D$20,""),"") -> Frame
A6: Wader Pools | C6: ='General Info and Liability'!B28 -> 0 | D6: Number | E6: 35000 | F6: =E6*C6 -> 0 | H6: =IFERROR(IF(H5+1<'General Info and Liability'!$B$15+1,'Property Schedule'!H5+1,""),"") | K6: =IFERROR(IF($H5+1<'General Info and Liability'!$B$15+1,'General Info and Liability'!$B$18/'General Info and Liability'!$B$10*$L6,""),"") | M6: =IFERROR(IF($H5+1<'General Info and Liability'!$B$15+1,'General Info and Liability'!$D$14/'General Info and Liability'!$B$10*$L6,""),"") | N6: =IFERROR(IF($H5+1<'General Info and Liability'!$B$15+1,'General Info and Liability'!$D$15/'General Info and Liability'!$B$10*$L6,""),"") | Q6: =IFERROR(IF($H6+1>0,'General Info and Liability'!$D$16,""),"") | R6: =IFERROR(IF($H6+1>0,'General Info and Liability'!$B$16,""),"") | S6: =IFERROR(IF($H5+1<'General Info and Liability'!$B$15+1,'General Info and Liability'!$D$17,""),"") | T6: =IFERROR(IF($H5+1<'General Info and Liability'!$B$15+1,'General Info and Liability'!$D$18,""),"") | U6: =IFERROR(IF($H5+1<'General Info and Liability'!$B$15+1,'General Info and Liability'!$D$19,""),"") | V6: =IFERROR(IF($H5+1<'General Info and Liability'!$B$15+1,'General Info and Liability'!$B$14,""),"") | W6: =IFERROR(IF($H5+1<'General Info and Liability'!$B$15+1,'General Info and Liability'!$D$20,""),"")
A7: Restroom Building | C7: ='General Info and Liability'!B29 -> 0 | D7: Sq Ft | E7: 175 | F7: =E7*C7 -> 0 | H7: =IFERROR(IF(H6+1<'General Info and Liability'!$B$15+1,'Property Schedule'!H6+1,""),"") | K7: =IFERROR(IF($H6+1<'General Info and Liability'!$B$15+1,'General Info and Liability'!$B$18/'General Info and Liability'!$B$10*$L7,""),"") | M7: =IFERROR(IF($H6+1<'General Info and Liability'!$B$15+1,'General Info and Liability'!$D$14/'General Info and Liability'!$B$10*$L7,""),"") | N7: =IFERROR(IF($H6+1<'General Info and Liability'!$B$15+1,'General Info and Liability'!$D$15/'General Info and Liability'!$B$10*$L7,""),"") | Q7: =IFERROR(IF($H7+1>0,'General Info and Liability'!$D$16,""),"") | R7: =IFERROR(IF($H7+1>0,'General Info and Liability'!$B$16,""),"") | S7: =IFERROR(IF($H6+1<'General Info and Liability'!$B$15+1,'General Info and Liability'!$D$17,""),"") | T7: =IFERROR(IF($H6+1<'General Info and Liability'!$B$15+1,'General Info and Liability'!$D$18,""),"") | U7: =IFERROR(IF($H6+1<'General Info and Liability'!$B$15+1,'General Info and Liability'!$D$19,""),"") | V7: =IFERROR(IF($H6+1<'General Info and Liability'!$B$15+1,'General Info and Liability'!$B$14,""),"") | W7: =IFERROR(IF($H6+1<'General Info and Liability'!$B$15+1,'General Info and Liability'!$D$20,""),"")
A8: Guardhouse | C8: ='General Info and Liability'!B30 -> 0 | D8: Sq Ft | E8: 175 | F8: =E8*C8 -> 0 | H8: =IFERROR(IF(H7+1<'General Info and Liability'!$B$15+1,'Property Schedule'!H7+1,""),"") | K8: =IFERROR(IF($H7+1<'General Info and Liability'!$B$15+1,'General Info and Liability'!$B$18/'General Info and Liability'!$B$10*$L8,""),"") | M8: =IFERROR(IF($H7+1<'General Info and Liability'!$B$15+1,'General Info and Liability'!$D$14/'General Info and Liability'!$B$10*$L8,""),"") | N8: =IFERROR(IF($H7+1<'General Info and Liability'!$B$15+1,'General Info and Liability'!$D$15/'General Info and Liability'!$B$10*$L8,""),"") | Q8: =IFERROR(IF($H8+1>0,'General Info and Liability'!$D$16,""),"") | R8: =IFERROR(IF($H8+1>0,'General Info and Liability'!$B$16,""),"") | S8: =IFERROR(IF($H7+1<'General Info and Liability'!$B$15+1,'General Info and Liability'!$D$17,""),"") | T8: =IFERROR(IF($H7+1<'General Info and Liability'!$B$15+1,'General Info and Liability'!$D$18,""),"") | U8: =IFERROR(IF($H7+1<'General Info and Liability'!$B$15+1,'General Info and Liability'!$D$19,""),"") | V8: =IFERROR(IF($H7+1<'General Info and Liability'!$B$15+1,'General Info and Liability'!$B$14,""),"") | W8: =IFERROR(IF($H7+1<'General Info and Liability'!$B$15+1,'General Info and Liability'!$D$20,""),"")
A9: Clubhouse | C9: ='General Info and Liability'!B31 -> 0 | D9: Sq Ft | E9: 175 | F9: =E9*C9 -> 0 | H9: =IFERROR(IF(H8+1<'General Info and Liability'!$B$15+1,'Property Schedule'!H8+1,""),"") | K9: =IFERROR(IF($H8+1<'General Info and Liability'!$B$15+1,'General Info and Liability'!$B$18/'General Info and Liability'!$B$10*$L9,""),"") | M9: =IFERROR(IF($H8+1<'General Info and Liability'!$B$15+1,'General Info and Liability'!$D$14/'General Info and Liability'!$B$10*$L9,""),"") | N9: =IFERROR(IF($H8+1<'General Info and Liability'!$B$15+1,'General Info and Liability'!$D$15/'General Info and Liability'!$B$10*$L9,""),"") | Q9: =IFERROR(IF($H9+1>0,'General Info and Liability'!$D$16,""),"") | R9: =IFERROR(IF($H9+1>0,'General Info and Liability'!$B$16,""),"") | S9: =IFERROR(IF($H8+1<'General Info and Liability'!$B$15+1,'General Info and Liability'!$D$17,""),"") | T9: =IFERROR(IF($H8+1<'General Info and Liability'!$B$15+1,'General Info and Liability'!$D$18,""),"") | U9: =IFERROR(IF($H8+1<'General Info and Liability'!$B$15+1,'General Info and Liability'!$D$19,""),"") | V9: =IFERROR(IF($H8+1<'General Info and Liability'!$B$15+1,'General Info and Liability'!$B$14,""),"") | W9: =IFERROR(IF($H8+1<'General Info and Liability'!$B$15+1,'General Info and Liability'!$D$20,""),"")
A10: Fitness Center | C10: ='General Info and Liability'!B32 -> 0 | D10: Sq Ft | E10: 175 | F10: =E10*C10 -> 0 | H10: =IFERROR(IF(H9+1<'General Info and Liability'!$B$15+1,'Property Schedule'!H9+1,""),"") | K10: =IFERROR(IF($H9+1<'General Info and Liability'!$B$15+1,'General Info and Liability'!$B$18/'General Info and Liability'!$B$10*$L10,""),"") | M10: =IFERROR(IF($H9+1<'General Info and Liability'!$B$15+1,'General Info and Liability'!$D$14/'General Info and Liability'!$B$10*$L10,""),"") | N10: =IFERROR(IF($H9+1<'General Info and Liability'!$B$15+1,'General Info and Liability'!$D$15/'General Info and Liability'!$B$10*$L10,""),"") | Q10: =IFERROR(IF($H10+1>0,'General Info and Liability'!$D$16,""),"") | R10: =IFERROR(IF($H10+1>0,'General Info and Liability'!$B$16,""),"") | S10: =IFERROR(IF($H9+1<'General Info and Liability'!$B$15+1,'General Info and Liability'!$D$17,""),"") | T10: =IFERROR(IF($H9+1<'General Info and Liability'!$B$15+1,'General Info and Liability'!$D$18,""),"") | U10: =IFERROR(IF($H9+1<'General Info and Liability'!$B$15+1,'General Info and Liability'!$D$19,""),"") | V10: =IFERROR(IF($H9+1<'General Info and Liability'!$B$15+1,'General Info and Liability'!$B$14,""),"") | W10: =IFERROR(IF($H9+1<'General Info and Liability'!$B$15+1,'General Info and Liability'!$D$20,""),"")
A11: Tennis Courts | C11: ='General Info and Liability'!B33 -> 0 | D11: Number | E11: 25000 | F11: =E11*C11 -> 0 | H11: =IFERROR(IF(H10+1<'General Info and Liability'!$B$15+1,'Property Schedule'!H10+1,""),"") | K11: =IFERROR(IF($H10+1<'General Info and Liability'!$B$15+1,'General Info and Liability'!$B$18/'General Info and Liability'!$B$10*$L11,""),"") | M11: =IFERROR(IF($H10+1<'General Info and Liability'!$B$15+1,'General Info and Liability'!$D$14/'General Info and Liability'!$B$10*$L11,""),"") | N11: =IFERROR(IF($H10+1<'General Info and Liability'!$B$15+1,'General Info and Liability'!$D$15/'General Info and Liability'!$B$10*$L11,""),"") | Q11: =IFERROR(IF($H11+1>0,'General Info and Liability'!$D$16,""),"") | R11: =IFERROR(IF($H11+1>0,'General Info and Liability'!$B$16,""),"") | S11: =IFERROR(IF($H10+1<'General Info and Liability'!$B$15+1,'General Info and Liability'!$D$17,""),"") | T11: =IFERROR(IF($H10+1<'General Info and Liability'!$B$15+1,'General Info and Liability'!$D$18,""),"") | U11: =IFERROR(IF($H10+1<'General Info and Liability'!$B$15+1,'General Info and Liability'!$D$19,""),"") | V11: =IFERROR(IF($H10+1<'General Info and Liability'!$B$15+1,'General Info and Liability'!$B$14,""),"") | W11: =IFERROR(IF($H10+1<'General Info and Liability'!$B$15+1,'General Info and Liability'!$D$20,""),"")
A12: Basketball Courts | C12: ='General Info and Liability'!B34 -> 0 | D12: Number | E12: 25000 | F12: =E12*C12 -> 0 | H12: =IFERROR(IF(H11+1<'General Info and Liability'!$B$15+1,'Property Schedule'!H11+1,""),"") | K12: =IFERROR(IF($H11+1<'General Info and Liability'!$B$15+1,'General Info and Liability'!$B$18/'General Info and Liability'!$B$10*$L12,""),"") | M12: =IFERROR(IF($H11+1<'General Info and Liability'!$B$15+1,'General Info and Liability'!$D$14/'General Info and Liability'!$B$10*$L12,""),"") | N12: =IFERROR(IF($H11+1<'General Info and Liability'!$B$15+1,'General Info and Liability'!$D$15/'General Info and Liability'!$B$10*$L12,""),"") | Q12: =IFERROR(IF($H12+1>0,'General Info and Liability'!$D$16,""),"") | R12: =IFERROR(IF($H12+1>0,'General Info and Liability'!$B$16,""),"") | S12: =IFERROR(IF($H11+1<'General Info and Liability'!$B$15+1,'General Info and Liability'!$D$17,""),"") | T12: =IFERROR(IF($H11+1<'General Info and Liability'!$B$15+1,'General Info and Liability'!$D$18,""),"") | U12: =IFERROR(IF($H11+1<'General Info and Liability'!$B$15+1,'General Info and Liability'!$D$19,""),"") | V12: =IFERROR(IF($H11+1<'General Info and Liability'!$B$15+1,'General Info and Liability'!$B$14,""),"") | W12: =IFERROR(IF($H11+1<'General Info and Liability'!$B$15+1,'General Info and Liability'!$D$20,""),"")
A13: Other Sport Courts | C13: ='General Info and Liability'!B35 -> 0 | D13: Number | E13: 25000 | F13: =E13*C13 -> 0 | H13: =IFERROR(IF(H12+1<'General Info and Liability'!$B$15+1,'Property Schedule'!H12+1,""),"") | K13: =IFERROR(IF($H12+1<'General Info and Liability'!$B$15+1,'General Info and Liability'!$B$18/'General Info and Liability'!$B$10*$L13,""),"") | M13: =IFERROR(IF($H12+1<'General Info and Liability'!$B$15+1,'General Info and Liability'!$D$14/'General Info and Liability'!$B$10*$L13,""),"") | N13: =IFERROR(IF($H12+1<'General Info and Liability'!$B$15+1,'General Info and Liability'!$D$15/'General Info and Liability'!$B$10*$L13,""),"") | Q13: =IFERROR(IF($H13+1>0,'General Info and Liability'!$D$16,""),"") | R13: =IFERROR(IF($H13+1>0,'General Info and Liability'!$B$16,""),"") | S13: =IFERROR(IF($H12+1<'General Info and Liability'!$B$15+1,'General Info and Liability'!$D$17,""),"") | T13: =IFERROR(IF($H12+1<'General Info and Liability'!$B$15+1,'General Info and Liability'!$D$18,""),"") | U13: =IFERROR(IF($H12+1<'General Info and Liability'!$B$15+1,'General Info and Liability'!$D$19,""),"") | V13: =IFERROR(IF($H12+1<'General Info and Liability'!$B$15+1,'General Info and Liability'!$B$14,""),"") | W13: =IFERROR(IF($H12+1<'General Info and Liability'!$B$15+1,'General Info and Liability'!$D$20,""),"")
A14: Walking / Biking Trails | C14: ='General Info and Liability'!B36 -> 0 | D14: Miles | E14: 500 | F14: =E14*C14 -> 0 | H14: =IFERROR(IF(H13+1<'General Info and Liability'!$B$15+1,'Property Schedule'!H13+1,""),"") | K14: =IFERROR(IF($H13+1<'General Info and Liability'!$B$15+1,'General Info and Liability'!$B$18/'General Info and Liability'!$B$10*$L14,""),"") | M14: =IFERROR(IF($H13+1<'General Info and Liability'!$B$15+1,'General Info and Liability'!$D$14/'General Info and Liability'!$B$10*$L14,""),"") | N14: =IFERROR(IF($H13+1<'General Info and Liability'!$B$15+1,'General Info and Liability'!$D$15/'General Info and Liability'!$B$10*$L14,""),"") | Q14: =IFERROR(IF($H14+1>0,'General Info and Liability'!$D$16,""),"") | R14: =IFERROR(IF($H14+1>0,'General Info and Liability'!$B$16,""),"") | S14: =IFERROR(IF($H13+1<'General Info and Liability'!$B$15+1,'General Info and Liability'!$D$17,""),"") | T14: =IFERROR(IF($H13+1<'General Info and Liability'!$B$15+1,'General Info and Liability'!$D$18,""),"") | U14: =IFERROR(IF($H13+1<'General Info and Liability'!$B$15+1,'General Info and Liability'!$D$19,""),"") | V14: =IFERROR(IF($H13+1<'General Info and Liability'!$B$15+1,'General Info and Liability'!$B$14,""),"") | W14: =IFERROR(IF($H13+1<'General Info and Liability'!$B$15+1,'General Info and Liability'!$D$20,""),"")
A15: Lakes or Ponds | C15: ='General Info and Liability'!B37 -> 0 | D15: Number | E15: 10000 | F15: =E15*C15 -> 0 | H15: =IFERROR(IF(H14+1<'General Info and Liability'!$B$15+1,'Property Schedule'!H14+1,""),"") | K15: =IFERROR(IF($H14+1<'General Info and Liability'!$B$15+1,'General Info and Liability'!$B$18/'General Info and Liability'!$B$10*$L15,""),"") | M15: =IFERROR(IF($H14+1<'General Info and Liability'!$B$15+1,'General Info and Liability'!$D$14/'General Info and Liability'!$B$10*$L15,""),"") | N15: =IFERROR(IF($H14+1<'General Info and Liability'!$B$15+1,'General Info and Liability'!$D$15/'General Info and Liability'!$B$10*$L15,""),"") | Q15: =IFERROR(IF($H15+1>0,'General Info and Liability'!$D$16,""),"") | R15: =IFERROR(IF($H15+1>0,'General Info and Liability'!$B$16,""),"") | S15: =IFERROR(IF($H14+1<'General Info and Liability'!$B$15+1,'General Info and Liability'!$D$17,""),"") | T15: =IFERROR(IF($H14+1<'General Info and Liability'!$B$15+1,'General Info and Liability'!$D$18,""),"") | U15: =IFERROR(IF($H14+1<'General Info and Liability'!$B$15+1,'General Info and Liability'!$D$19,""),"") | V15: =IFERROR(IF($H14+1<'General Info and Liability'!$B$15+1,'General Info and Liability'!$B$14,""),"") | W15: =IFERROR(IF($H14+1<'General Info and Liability'!$B$15+1,'General Info and Liability'!$D$20,""),"")
A16: Boat Docks and Slips | C16: ='General Info and Liability'!B38 -> 0 | D16: Number | E16: 5000 | F16: =E16*C16 -> 0 | H16: =IFERROR(IF(H15+1<'General Info and Liability'!$B$15+1,'Property Schedule'!H15+1,""),"") | K16: =IFERROR(IF($H15+1<'General Info and Liability'!$B$15+1,'General Info and Liability'!$B$18/'General Info and Liability'!$B$10*$L16,""),"") | M16: =IFERROR(IF($H15+1<'General Info and Liability'!$B$15+1,'General Info and Liability'!$D$14/'General Info and Liability'!$B$10*$L16,""),"") | N16: =IFERROR(IF($H15+1<'General Info and Liability'!$B$15+1,'General Info and Liability'!$D$15/'General Info and Liability'!$B$10*$L16,""),"") | Q16: =IFERROR(IF($H16+1>0,'General Info and Liability'!$D$16,""),"") | R16: =IFERROR(IF($H16+1>0,'General Info and Liability'!$B$16,""),"") | S16: =IFERROR(IF($H15+1<'General Info and Liability'!$B$15+1,'General Info and Liability'!$D$17,""),"") | T16: =IFERROR(IF($H15+1<'General Info and Liability'!$B$15+1,'General Info and Liability'!$D$18,""),"") | U16: =IFERROR(IF($H15+1<'General Info and Liability'!$B$15+1,'General Info and Liability'!$D$19,""),"") | V16: =IFERROR(IF($H15+1<'General Info and Liability'!$B$15+1,'General Info and Liability'!$B$14,""),"") | W16: =IFERROR(IF($H15+1<'General Info and Liability'!$B$15+1,'General Info and Liability'!$D$20,""),"")
A17: Dog Parks | C17: ='General Info and Liability'!B39 -> 0 | D17: Number | E17: 20000 | F17: =E17*C17 -> 0 | H17: =IFERROR(IF(H16+1<'General Info and Liability'!$B$15+1,'Property Schedule'!H16+1,""),"") | K17: =IFERROR(IF($H16+1<'General Info and Liability'!$B$15+1,'General Info and Liability'!$B$18/'General Info and Liability'!$B$10*$L17,""),"") | M17: =IFERROR(IF($H16+1<'General Info and Liability'!$B$15+1,'General Info and Liability'!$D$14/'General Info and Liability'!$B$10*$L17,""),"") | N17: =IFERROR(IF($H16+1<'General Info and Liability'!$B$15+1,'General Info and Liability'!$D$15/'General Info and Liability'!$B$10*$L17,""),"") | Q17: =IFERROR(IF($H17+1>0,'General Info and Liability'!$D$16,""),"") | R17: =IFERROR(IF($H17+1>0,'General Info and Liability'!$B$16,""),"") | S17: =IFERROR(IF($H16+1<'General Info and Liability'!$B$15+1,'General Info and Liability'!$D$17,""),"") | T17: =IFERROR(IF($H16+1<'General Info and Liability'!$B$15+1,'General Info and Liability'!$D$18,""),"") | U17: =IFERROR(IF($H16+1<'General Info and Liability'!$B$15+1,'General Info and Liability'!$D$19,""),"") | V17: =IFERROR(IF($H16+1<'General Info and Liability'!$B$15+1,'General Info and Liability'!$B$14,""),"") | W17: =IFERROR(IF($H16+1<'General Info and Liability'!$B$15+1,'General Info and Liability'!$D$20,""),"")
A18: Elevators | C18: ='General Info and Liability'!B40 -> 0 | D18: Number | E18: 15000 | F18: =E18*C18 -> 0 | H18: =IFERROR(IF(H17+1<'General Info and Liability'!$B$15+1,'Property Schedule'!H17+1,""),"") | K18: =IFERROR(IF($H17+1<'General Info and Liability'!$B$15+1,'General Info and Liability'!$B$18/'General Info and Liability'!$B$10*$L18,""),"") | M18: =IFERROR(IF($H17+1<'General Info and Liability'!$B$15+1,'General Info and Liability'!$D$14/'General Info and Liability'!$B$10*$L18,""),"") | N18: =IFERROR(IF($H17+1<'General Info and Liability'!$B$15+1,'General Info and Liability'!$D$15/'General Info and Liability'!$B$10*$L18,""),"") | Q18: =IFERROR(IF($H18+1>0,'General Info and Liability'!$D$16,""),"") | R18: =IFERROR(IF($H18+1>0,'General Info and Liability'!$B$16,""),"") | S18: =IFERROR(IF($H17+1<'General Info and Liability'!$B$15+1,'General Info and Liability'!$D$17,""),"") | T18: =IFERROR(IF($H17+1<'General Info and Liability'!$B$15+1,'General Info and Liability'!$D$18,""),"") | U18: =IFERROR(IF($H17+1<'General Info and Liability'!$B$15+1,'General Info and Liability'!$D$19,""),"") | V18: =IFERROR(IF($H17+1<'General Info and Liability'!$B$15+1,'General Info and Liability'!$B$14,""),"") | W18: =IFERROR(IF($H17+1<'General Info and Liability'!$B$15+1,'General Info and Liability'!$D$20,""),"")
A19: Walls/Fences | F19: 50000 | H19: =IFERROR(IF(H18+1<'General Info and Liability'!$B$15+1,'Property Schedule'!H18+1,""),"") | K19: =IFERROR(IF($H18+1<'General Info and Liability'!$B$15+1,'General Info and Liability'!$B$18/'General Info and Liability'!$B$10*$L19,""),"") | M19: =IFERROR(IF($H18+1<'General Info and Liability'!$B$15+1,'General Info and Liability'!$D$14/'General Info and Liability'!$B$10*$L19,""),"") | N19: =IFERROR(IF($H18+1<'General Info and Liability'!$B$15+1,'General Info and Liability'!$D$15/'General Info and Liability'!$B$10*$L19,""),"") | Q19: =IFERROR(IF($H19+1>0,'General Info and Liability'!$D$16,""),"") | R19: =IFERROR(IF($H19+1>0,'General Info and Liability'!$B$16,""),"") | S19: =IFERROR(IF($H18+1<'General Info and Liability'!$B$15+1,'General Info and Liability'!$D$17,""),"") | T19: =IFERROR(IF($H18+1<'General Info and Liability'!$B$15+1,'General Info and Liability'!$D$18,""),"") | U19: =IFERROR(IF($H18+1<'General Info and Liability'!$B$15+1,'General Info and Liability'!$D$19,""),"") | V19: =IFERROR(IF($H18+1<'General Info and Liability'!$B$15+1,'General Info and Liability'!$B$14,""),"") | W19: =IFERROR(IF($H18+1<'General Info and Liability'!$B$15+1,'General Info and Liability'!$D$20,""),"")
A20: Sidewalks/Curbs/Walkways/Pavers | F20: 15000 | H20: =IFERROR(IF(H19+1<'General Info and Liability'!$B$15+1,'Property Schedule'!H19+1,""),"") | K20: =IFERROR(IF($H19+1<'General Info and Liability'!$B$15+1,'General Info and Liability'!$B$18/'General Info and Liability'!$B$10*$L20,""),"") | M20: =IFERROR(IF($H19+1<'General Info and Liability'!$B$15+1,'General Info and Liability'!$D$14/'General Info and Liability'!$B$10*$L20,""),"") | N20: =IFERROR(IF($H19+1<'General Info and Liability'!$B$15+1,'General Info and Liability'!$D$15/'General Info and Liability'!$B$10*$L20,""),"") | Q20: =IFERROR(IF($H20+1>0,'General Info and Liability'!$D$16,""),"") | R20: =IFERROR(IF($H20+1>0,'General Info and Liability'!$B$16,""),"") | S20: =IFERROR(IF($H19+1<'General Info and Liability'!$B$15+1,'General Info and Liability'!$D$17,""),"") | T20: =IFERROR(IF($H19+1<'General Info and Liability'!$B$15+1,'General Info and Liability'!$D$18,""),"") | U20: =IFERROR(IF($H19+1<'General Info and Liability'!$B$15+1,'General Info and Liability'!$D$19,""),"") | V20: =IFERROR(IF($H19+1<'General Info and Liability'!$B$15+1,'General Info and Liability'!$B$14,""),"") | W20: =IFERROR(IF($H19+1<'General Info and Liability'!$B$15+1,'General Info and Liability'!$D$20,""),"")
A21: Irrigation System | F21: 10000 | H21: =IFERROR(IF(H20+1<'General Info and Liability'!$B$15+1,'Property Schedule'!H20+1,""),"") | K21: =IFERROR(IF($H20+1<'General Info and Liability'!$B$15+1,'General Info and Liability'!$B$18/'General Info and Liability'!$B$10*$L21,""),"") | M21: =IFERROR(IF($H20+1<'General Info and Liability'!$B$15+1,'General Info and Liability'!$D$14/'General Info and Liability'!$B$10*$L21,""),"") | N21: =IFERROR(IF($H20+1<'General Info and Liability'!$B$15+1,'General Info and Liability'!$D$15/'General Info and Liability'!$B$10*$L21,""),"") | Q21: =IFERROR(IF($H21+1>0,'General Info and Liability'!$D$16,""),"") | R21: =IFERROR(IF($H21+1>0,'General Info and Liability'!$B$16,""),"") | S21: =IFERROR(IF($H20+1<'General Info and Liability'!$B$15+1,'General Info and Liability'!$D$17,""),"") | T21: =IFERROR(IF($H20+1<'General Info and Liability'!$B$15+1,'General Info and Liability'!$D$18,""),"") | U21: =IFERROR(IF($H20+1<'General Info and Liability'!$B$15+1,'General Info and Liability'!$D$19,""),"") | V21: =IFERROR(IF($H20+1<'General Info and Liability'!$B$15+1,'General Info and Liability'!$B$14,""),"") | W21: =IFERROR(IF($H20+1<'General Info and Liability'!$B$15+1,'General Info and Liability'!$D$20,""),"")
A22: Lights/Poles | F22: 15000 | H22: =IFERROR(IF(H21+1<'General Info and Liability'!$B$15+1,'Property Schedule'!H21+1,""),"") | K22: =IFERROR(IF($H21+1<'General Info and Liability'!$B$15+1,'General Info and Liability'!$B$18/'General Info and Liability'!$B$10*$L22,""),"") | M22: =IFERROR(IF($H21+1<'General Info and Liability'!$B$15+1,'General Info and Liability'!$D$14/'General Info and Liability'!$B$10*$L22,""),"") | N22: =IFERROR(IF($H21+1<'General Info and Liability'!$B$15+1,'General Info and Liability'!$D$15/'General Info and Liability'!$B$10*$L22,""),"") | Q22: =IFERROR(IF($H22+1>0,'General Info and Liability'!$D$16,""),"") | R22: =IFERROR(IF($H22+1>0,'General Info and Liability'!$B$16,""),"") | S22: =IFERROR(IF($H21+1<'General Info and Liability'!$B$15+1,'General Info and Liability'!$D$17,""),"") | T22: =IFERROR(IF($H21+1<'General Info and Liability'!$B$15+1,'General Info and Liability'!$D$18,""),"") | U22: =IFERROR(IF($H21+1<'General Info and Liability'!$B$15+1,'General Info and Liability'!$D$19,""),"") | V22: =IFERROR(IF($H21+1<'General Info and Liability'!$B$15+1,'General Info and Liability'!$B$14,""),"") | W22: =IFERROR(IF($H21+1<'General Info and Liability'!$B$15+1,'General Info and Liability'!$D$20,""),"")
A23: Mailboxes | F23: 5000 | H23: =IFERROR(IF(H22+1<'General Info and Liability'!$B$15+1,'Property Schedule'!H22+1,""),"") | K23: =IFERROR(IF($H22+1<'General Info and Liability'!$B$15+1,'General Info and Liability'!$B$18/'General Info and Liability'!$B$10*$L23,""),"") | M23: =IFERROR(IF($H22+1<'General Info and Liability'!$B$15+1,'General Info and Liability'!$D$14/'General Info and Liability'!$B$10*$L23,""),"") | N23: =IFERROR(IF($H22+1<'General Info and Liability'!$B$15+1,'General Info and Liability'!$D$15/'General Info and Liability'!$B$10*$L23,""),"") | Q23: =IFERROR(IF($H23+1>0,'General Info and Liability'!$D$16,""),"") | R23: =IFERROR(IF($H23+1>0,'General Info and Liability'!$B$16,""),"") | S23: =IFERROR(IF($H22+1<'General Info and Liability'!$B$15+1,'General Info and Liability'!$D$17,""),"") | T23: =IFERROR(IF($H22+1<'General Info and Liability'!$B$15+1,'General Info and Liability'!$D$18,""),"") | U23: =IFERROR(IF($H22+1<'General Info and Liability'!$B$15+1,'General Info and Liability'!$D$19,""),"") | V23: =IFERROR(IF($H22+1<'General Info and Liability'!$B$15+1,'General Info and Liability'!$B$14,""),"") | W23: =IFERROR(IF($H22+1<'General Info and Liability'!$B$15+1,'General Info and Liability'!$D$20,""),"")
A24: Signs/Monuments/Fire Hydrants | F24: 5000 | H24: =IFERROR(IF(H23+1<'General Info and Liability'!$B$15+1,'Property Schedule'!H23+1,""),"") | K24: =IFERROR(IF($H23+1<'General Info and Liability'!$B$15+1,'General Info and Liability'!$B$18/'General Info and Liability'!$B$10*$L24,""),"") | M24: =IFERROR(IF($H23+1<'General Info and Liability'!$B$15+1,'General Info and Liability'!$D$14/'General Info and Liability'!$B$10*$L24,""),"") | N24: =IFERROR(IF($H23+1<'General Info and Liability'!$B$15+1,'General Info and Liability'!$D$15/'General Info and Liability'!$B$10*$L24,""),"") | Q24: =IFERROR(IF($H24+1>0,'General Info and Liability'!$D$16,""),"") | R24: =IFERROR(IF($H24+1>0,'General Info and Liability'!$B$16,""),"") | S24: =IFERROR(IF($H23+1<'General Info and Liability'!$B$15+1,'General Info and Liability'!$D$17,""),"") | T24: =IFERROR(IF($H23+1<'General Info and Liability'!$B$15+1,'General Info and Liability'!$D$18,""),"") | U24: =IFERROR(IF($H23+1<'General Info and Liability'!$B$15+1,'General Info and Liability'!$D$19,""),"") | V24: =IFERROR(IF($H23+1<'General Info and Liability'!$B$15+1,'General Info and Liability'!$B$14,""),"") | W24: =IFERROR(IF($H23+1<'General Info and Liability'!$B$15+1,'General Info and Liability'!$D$20,""),"")
A25: Gates/Entry Features | F25: 25000 | H25: =IFERROR(IF(H24+1<'General Info and Liability'!$B$15+1,'Property Schedule'!H24+1,""),"") | K25: =IFERROR(IF($H24+1<'General Info and Liability'!$B$15+1,'General Info and Liability'!$B$18/'General Info and Liability'!$B$10*$L25,""),"") | M25: =IFERROR(IF($H24+1<'General Info and Liability'!$B$15+1,'General Info and Liability'!$D$14/'General Info and Liability'!$B$10*$L25,""),"") | N25: =IFERROR(IF($H24+1<'General Info and Liability'!$B$15+1,'General Info and Liability'!$D$15/'General Info and Liability'!$B$10*$L25,""),"") | Q25: =IFERROR(IF($H25+1>0,'General Info and Liability'!$D$16,""),"") | R25: =IFERROR(IF($H25+1>0,'General Info and Liability'!$B$16,""),"") | S25: =IFERROR(IF($H24+1<'General Info and Liability'!$B$15+1,'General Info and Liability'!$D$17,""),"") | T25: =IFERROR(IF($H24+1<'General Info and Liability'!$B$15+1,'General Info and Liability'!$D$18,""),"") | U25: =IFERROR(IF($H24+1<'General Info and Liability'!$B$15+1,'General Info and Liability'!$D$19,""),"") | V25: =IFERROR(IF($H24+1<'General Info and Liability'!$B$15+1,'General Info and Liability'!$B$14,""),"") | W25: =IFERROR(IF($H24+1<'General Info and Liability'!$B$15+1,'General Info and Liability'!$D$20,""),"")
A26: Ramada/Cabana | H26: =IFERROR(IF(H25+1<'General Info and Liability'!$B$15+1,'Property Schedule'!H25+1,""),"") | K26: =IFERROR(IF($H25+1<'General Info and Liability'!$B$15+1,'General Info and Liability'!$B$18/'General Info and Liability'!$B$10*$L26,""),"") | M26: =IFERROR(IF($H25+1<'General Info and Liability'!$B$15+1,'General Info and Liability'!$D$14/'General Info and Liability'!$B$10*$L26,""),"") | N26: =IFERROR(IF($H25+1<'General Info and Liability'!$B$15+1,'General Info and Liability'!$D$15/'General Info and Liability'!$B$10*$L26,""),"") | Q26: =IFERROR(IF($H26+1>0,'General Info and Liability'!$D$16,""),"") | R26: =IFERROR(IF($H26+1>0,'General Info and Liability'!$B$16,""),"") | S26: =IFERROR(IF($H25+1<'General Info and Liability'!$B$15+1,'General Info and Liability'!$D$17,""),"") | T26: =IFERROR(IF($H25+1<'General Info and Liability'!$B$15+1,'General Info and Liability'!$D$18,""),"") | U26: =IFERROR(IF($H25+1<'General Info and Liability'!$B$15+1,'General Info and Liability'!$D$19,""),"") | V26: =IFERROR(IF($H25+1<'General Info and Liability'!$B$15+1,'General Info and Liability'!$B$14,""),"") | W26: =IFERROR(IF($H25+1<'General Info and Liability'!$B$15+1,'General Info and Liability'!$D$20,""),"")
A27: Park Furniture | H27: =IFERROR(IF(H26+1<'General Info and Liability'!$B$15+1,'Property Schedule'!H26+1,""),"") | K27: =IFERROR(IF($H26+1<'General Info and Liability'!$B$15+1,'General Info and Liability'!$B$18/'General Info and Liability'!$B$10*$L27,""),"") | M27: =IFERROR(IF($H26+1<'General Info and Liability'!$B$15+1,'General Info and Liability'!$D$14/'General Info and Liability'!$B$10*$L27,""),"") | N27: =IFERROR(IF($H26+1<'General Info and Liability'!$B$15+1,'General Info and Liability'!$D$15/'General Info and Liability'!$B$10*$L27,""),"") | Q27: =IFERROR(IF($H27+1>0,'General Info and Liability'!$D$16,""),"") | R27: =IFERROR(IF($H27+1>0,'General Info and Liability'!$B$16,""),"") | S27: =IFERROR(IF($H26+1<'General Info and Liability'!$B$15+1,'General Info and Liability'!$D$17,""),"") | T27: =IFERROR(IF($H26+1<'General Info and Liability'!$B$15+1,'General Info and Liability'!$D$18,""),"") | U27: =IFERROR(IF($H26+1<'General Info and Liability'!$B$15+1,'General Info and Liability'!$D$19,""),"") | V27: =IFERROR(IF($H26+1<'General Info and Liability'!$B$15+1,'General Info and Liability'!$B$14,""),"") | W27: =IFERROR(IF($H26+1<'General Info and Liability'!$B$15+1,'General Info and Liability'!$D$20,""),"")
A28: Trashcans | F28: 5000 | H28: =IFERROR(IF(H27+1<'General Info and Liability'!$B$15+1,'Property Schedule'!H27+1,""),"") | K28: =IFERROR(IF($H27+1<'General Info and Liability'!$B$15+1,'General Info and Liability'!$B$18/'General Info and Liability'!$B$10*$L28,""),"") | M28: =IFERROR(IF($H27+1<'General Info and Liability'!$B$15+1,'General Info and Liability'!$D$14/'General Info and Liability'!$B$10*$L28,""),"") | N28: =IFERROR(IF($H27+1<'General Info and Liability'!$B$15+1,'General Info and Liability'!$D$15/'General Info and Liability'!$B$10*$L28,""),"") | Q28: =IFERROR(IF($H28+1>0,'General Info and Liability'!$D$16,""),"") | R28: =IFERROR(IF($H28+1>0,'General Info and Liability'!$B$16,""),"") | S28: =IFERROR(IF($H27+1<'General Info and Liability'!$B$15+1,'General Info and Liability'!$D$17,""),"") | T28: =IFERROR(IF($H27+1<'General Info and Liability'!$B$15+1,'General Info and Liability'!$D$18,""),"") | U28: =IFERROR(IF($H27+1<'General Info and Liability'!$B$15+1,'General Info and Liability'!$D$19,""),"") | V28: =IFERROR(IF($H27+1<'General Info and Liability'!$B$15+1,'General Info and Liability'!$B$14,""),"") | W28: =IFERROR(IF($H27+1<'General Info and Liability'!$B$15+1,'General Info and Liability'!$D$20,""),"")
A29: BBQ Grills | H29: =IFERROR(IF(H28+1<'General Info and Liability'!$B$15+1,'Property Schedule'!H28+1,""),"") | K29: =IFERROR(IF($H28+1<'General Info and Liability'!$B$15+1,'General Info and Liability'!$B$18/'General Info and Liability'!$B$10*$L29,""),"") | M29: =IFERROR(IF($H28+1<'General Info and Liability'!$B$15+1,'General Info and Liability'!$D$14/'General Info and Liability'!$B$10*$L29,""),"") | N29: =IFERROR(IF($H28+1<'General Info and Liability'!$B$15+1,'General Info and Liability'!$D$15/'General Info and Liability'!$B$10*$L29,""),"") | Q29: =IFERROR(IF($H29+1>0,'General Info and Liability'!$D$16,""),"") | R29: =IFERROR(IF($H29+1>0,'General Info and Liability'!$B$16,""),"") | S29: =IFERROR(IF($H28+1<'General Info and Liability'!$B$15+1,'General Info and Liability'!$D$17,""),"") | T29: =IFERROR(IF($H28+1<'General Info and Liability'!$B$15+1,'General Info and Liability'!$D$18,""),"") | U29: =IFERROR(IF($H28+1<'General Info and Liability'!$B$15+1,'General Info and Liability'!$D$19,""),"") | V29: =IFERROR(IF($H28+1<'General Info and Liability'!$B$15+1,'General Info and Liability'!$B$14,""),"") | W29: =IFERROR(IF($H28+1<'General Info and Liability'!$B$15+1,'General Info and Liability'!$D$20,""),"")
A30: Drinking Fountains | H30: =IFERROR(IF(H29+1<'General Info and Liability'!$B$15+1,'Property Schedule'!H29+1,""),"") | K30: =IFERROR(IF($H29+1<'General Info and Liability'!$B$15+1,'General Info and Liability'!$B$18/'General Info and Liability'!$B$10*$L30,""),"") | M30: =IFERROR(IF($H29+1<'General Info and Liability'!$B$15+1,'General Info and Liability'!$D$14/'General Info and Liability'!$B$10*$L30,""),"") | N30: =IFERROR(IF($H29+1<'General Info and Liability'!$B$15+1,'General Info and Liability'!$D$15/'General Info and Liability'!$B$10*$L30,""),"") | Q30: =IFERROR(IF($H30+1>0,'General Info and Liability'!$D$16,""),"") | R30: =IFERROR(IF($H30+1>0,'General Info and Liability'!$B$16,""),"") | S30: =IFERROR(IF($H29+1<'General Info and Liability'!$B$15+1,'General Info and Liability'!$D$17,""),"") | T30: =IFERROR(IF($H29+1<'General Info and Liability'!$B$15+1,'General Info and Liability'!$D$18,""),"") | U30: =IFERROR(IF($H29+1<'General Info and Liability'!$B$15+1,'General Info and Liability'!$D$19,""),"") | V30: =IFERROR(IF($H29+1<'General Info and Liability'!$B$15+1,'General Info and Liability'!$B$14,""),"") | W30: =IFERROR(IF($H29+1<'General Info and Liability'!$B$15+1,'General Info and Liability'!$D$20,""),"")
A31: Doggie Stations | H31: =IFERROR(IF(H30+1<'General Info and Liability'!$B$15+1,'Property Schedule'!H30+1,""),"") | K31: =IFERROR(IF($H30+1<'General Info and Liability'!$B$15+1,'General Info and Liability'!$B$18/'General Info and Liability'!$B$10*$L31,""),"") | M31: =IFERROR(IF($H30+1<'General Info and Liability'!$B$15+1,'General Info and Liability'!$D$14/'General Info and Liability'!$B$10*$L31,""),"") | N31: =IFERROR(IF($H30+1<'General Info and Liability'!$B$15+1,'General Info and Liability'!$D$15/'General Info and Liability'!$B$10*$L31,""),"") | Q31: =IFERROR(IF($H31+1>0,'General Info and Liability'!$D$16,""),"") | R31: =IFERROR(IF($H31+1>0,'General Info and Liability'!$B$16,""),"") | S31: =IFERROR(IF($H30+1<'General Info and Liability'!$B$15+1,'General Info and Liability'!$D$17,""),"") | T31: =IFERROR(IF($H30+1<'General Info and Liability'!$B$15+1,'General Info and Liability'!$D$18,""),"") | U31: =IFERROR(IF($H30+1<'General Info and Liability'!$B$15+1,'General Info and Liability'!$D$19,""),"") | V31: =IFERROR(IF($H30+1<'General Info and Liability'!$B$15+1,'General Info and Liability'!$B$14,""),"") | W31: =IFERROR(IF($H30+1<'General Info and Liability'!$B$15+1,'General Info and Liability'!$D$20,""),"")
A32: Drywells | H32: =IFERROR(IF(H31+1<'General Info and Liability'!$B$15+1,'Property Schedule'!H31+1,""),"") | K32: =IFERROR(IF($H31+1<'General Info and Liability'!$B$15+1,'General Info and Liability'!$B$18/'General Info and Liability'!$B$10*$L32,""),"") | M32: =IFERROR(IF($H31+1<'General Info and Liability'!$B$15+1,'General Info and Liability'!$D$14/'General Info and Liability'!$B$10*$L32,""),"") | N32: =IFERROR(IF($H31+1<'General Info and Liability'!$B$15+1,'General Info and Liability'!$D$15/'General Info and Liability'!$B$10*$L32,""),"") | Q32: =IFERROR(IF($H32+1>0,'General Info and Liability'!$D$16,""),"") | R32: =IFERROR(IF($H32+1>0,'General Info and Liability'!$B$16,""),"") | S32: =IFERROR(IF($H31+1<'General Info and Liability'!$B$15+1,'General Info and Liability'!$D$17,""),"") | T32: =IFERROR(IF($H31+1<'General Info and Liability'!$B$15+1,'General Info and Liability'!$D$18,""),"") | U32: =IFERROR(IF($H31+1<'General Info and Liability'!$B$15+1,'General Info and Liability'!$D$19,""),"") | V32: =IFERROR(IF($H31+1<'General Info and Liability'!$B$15+1,'General Info and Liability'!$B$14,""),"") | W32: =IFERROR(IF($H31+1<'General Info and Liability'!$B$15+1,'General Info and Liability'!$D$20,""),"")
A33: Other: | C33: Security Cameras | F33: 10000 | H33: =IFERROR(IF(H32+1<'General Info and Liability'!$B$15+1,'Property Schedule'!H32+1,""),"") | K33: =IFERROR(IF($H32+1<'General Info and Liability'!$B$15+1,'General Info and Liability'!$B$18/'General Info and Liability'!$B$10*$L33,""),"") | M33: =IFERROR(IF($H32+1<'General Info and Liability'!$B$15+1,'General Info and Liability'!$D$14/'General Info and Liability'!$B$10*$L33,""),"") | N33: =IFERROR(IF($H32+1<'General Info and Liability'!$B$15+1,'General Info and Liability'!$D$15/'General Info and Liability'!$B$10*$L33,""),"") | Q33: =IFERROR(IF($H33+1>0,'General Info and Liability'!$D$16,""),"") | R33: =IFERROR(IF($H33+1>0,'General Info and Liability'!$B$16,""),"") | S33: =IFERROR(IF($H32+1<'General Info and Liability'!$B$15+1,'General Info and Liability'!$D$17,""),"") | T33: =IFERROR(IF($H32+1<'General Info and Liability'!$B$15+1,'General Info and Liability'!$D$18,""),"") | U33: =IFERROR(IF($H32+1<'General Info and Liability'!$B$15+1,'General Info and Liability'!$D$19,""),"") | V33: =IFERROR(IF($H32+1<'General Info and Liability'!$B$15+1,'General Info and Liability'!$B$14,""),"") | W33: =IFERROR(IF($H32+1<'General Info and Liability'!$B$15+1,'General Info and Liability'!$D$20,""),"")
A34: Other: | H34: =IFERROR(IF(H33+1<'General Info and Liability'!$B$15+1,'Property Schedule'!H33+1,""),"") | K34: =IFERROR(IF($H33+1<'General Info and Liability'!$B$15+1,'General Info and Liability'!$B$18/'General Info and Liability'!$B$10*$L34,""),"") | M34: =IFERROR(IF($H33+1<'General Info and Liability'!$B$15+1,'General Info and Liability'!$D$14/'General Info and Liability'!$B$10*$L34,""),"") | N34: =IFERROR(IF($H33+1<'General Info and Liability'!$B$15+1,'General Info and Liability'!$D$15/'General Info and Liability'!$B$10*$L34,""),"") | Q34: =IFERROR(IF($H34+1>0,'General Info and Liability'!$D$16,""),"") | R34: =IFERROR(IF($H34+1>0,'General Info and Liability'!$B$16,""),"") | S34: =IFERROR(IF($H33+1<'General Info and Liability'!$B$15+1,'General Info and Liability'!$D$17,""),"") | T34: =IFERROR(IF($H33+1<'General Info and Liability'!$B$15+1,'General Info and Liability'!$D$18,""),"") | U34: =IFERROR(IF($H33+1<'General Info and Liability'!$B$15+1,'General Info and Liability'!$D$19,""),"") | V34: =IFERROR(IF($H33+1<'General Info and Liability'!$B$15+1,'General Info and Liability'!$B$14,""),"") | W34: =IFERROR(IF($H33+1<'General Info and Liability'!$B$15+1,'General Info and Liability'!$D$20,""),"")
A35: Other: | H35: =IFERROR(IF(H34+1<'General Info and Liability'!$B$15+1,'Property Schedule'!H34+1,""),"") | K35: =IFERROR(IF($H34+1<'General Info and Liability'!$B$15+1,'General Info and Liability'!$B$18/'General Info and Liability'!$B$10*$L35,""),"") | M35: =IFERROR(IF($H34+1<'General Info and Liability'!$B$15+1,'General Info and Liability'!$D$14/'General Info and Liability'!$B$10*$L35,""),"") | N35: =IFERROR(IF($H34+1<'General Info and Liability'!$B$15+1,'General Info and Liability'!$D$15/'General Info and Liability'!$B$10*$L35,""),"") | Q35: =IFERROR(IF($H35+1>0,'General Info and Liability'!$D$16,""),"") | R35: =IFERROR(IF($H35+1>0,'General Info and Liability'!$B$16,""),"") | S35: =IFERROR(IF($H34+1<'General Info and Liability'!$B$15+1,'General Info and Liability'!$D$17,""),"") | T35: =IFERROR(IF($H34+1<'General Info and Liability'!$B$15+1,'General Info and Liability'!$D$18,""),"") | U35: =IFERROR(IF($H34+1<'General Info and Liability'!$B$15+1,'General Info and Liability'!$D$19,""),"") | V35: =IFERROR(IF($H34+1<'General Info and Liability'!$B$15+1,'General Info and Liability'!$B$14,""),"") | W35: =IFERROR(IF($H34+1<'General Info and Liability'!$B$15+1,'General Info and Liability'!$D$20,""),"")
A36: Other: | H36: =IFERROR(IF(H35+1<'General Info and Liability'!$B$15+1,'Property Schedule'!H35+1,""),"") | K36: =IFERROR(IF($H35+1<'General Info and Liability'!$B$15+1,'General Info and Liability'!$B$18/'General Info and Liability'!$B$10*$L36,""),"") | M36: =IFERROR(IF($H35+1<'General Info and Liability'!$B$15+1,'General Info and Liability'!$D$14/'General Info and Liability'!$B$10*$L36,""),"") | N36: =IFERROR(IF($H35+1<'General Info and Liability'!$B$15+1,'General Info and Liability'!$D$15/'General Info and Liability'!$B$10*$L36,""),"") | Q36: =IFERROR(IF($H36+1>0,'General Info and Liability'!$D$16,""),"") | R36: =IFERROR(IF($H36+1>0,'General Info and Liability'!$B$16,""),"") | S36: =IFERROR(IF($H35+1<'General Info and Liability'!$B$15+1,'General Info and Liability'!$D$17,""),"") | T36: =IFERROR(IF($H35+1<'General Info and Liability'!$B$15+1,'General Info and Liability'!$D$18,""),"") | U36: =IFERROR(IF($H35+1<'General Info and Liability'!$B$15+1,'General Info and Liability'!$D$19,""),"") | V36: =IFERROR(IF($H35+1<'General Info and Liability'!$B$15+1,'General Info and Liability'!$B$14,""),"") | W36: =IFERROR(IF($H35+1<'General Info and Liability'!$B$15+1,'General Info and Liability'!$D$20,""),"")
A37: Other: | H37: =IFERROR(IF(H36+1<'General Info and Liability'!$B$15+1,'Property Schedule'!H36+1,""),"") | K37: =IFERROR(IF($H36+1<'General Info and Liability'!$B$15+1,'General Info and Liability'!$B$18/'General Info and Liability'!$B$10*$L37,""),"") | M37: =IFERROR(IF($H36+1<'General Info and Liability'!$B$15+1,'General Info and Liability'!$D$14/'General Info and Liability'!$B$10*$L37,""),"") | N37: =IFERROR(IF($H36+1<'General Info and Liability'!$B$15+1,'General Info and Liability'!$D$15/'General Info and Liability'!$B$10*$L37,""),"") | Q37: =IFERROR(IF($H37+1>0,'General Info and Liability'!$D$16,""),"") | R37: =IFERROR(IF($H37+1>0,'General Info and Liability'!$B$16,""),"") | S37: =IFERROR(IF($H36+1<'General Info and Liability'!$B$15+1,'General Info and Liability'!$D$17,""),"") | T37: =IFERROR(IF($H36+1<'General Info and Liability'!$B$15+1,'General Info and Liability'!$D$18,""),"") | U37: =IFERROR(IF($H36+1<'General Info and Liability'!$B$15+1,'General Info and Liability'!$D$19,""),"") | V37: =IFERROR(IF($H36+1<'General Info and Liability'!$B$15+1,'General Info and Liability'!$B$14,""),"") | W37: =IFERROR(IF($H36+1<'General Info and Liability'!$B$15+1,'General Info and Liability'!$D$20,""),"")
A38: Total Common Area Property | F38: =SUM(F2:F37) -> 140000 | H38: =IFERROR(IF(H37+1<'General Info and Liability'!$B$15+1,'Property Schedule'!H37+1,""),"") | K38: =IFERROR(IF($H37+1<'General Info and Liability'!$B$15+1,'General Info and Liability'!$B$18/'General Info and Liability'!$B$10*$L38,""),"") | M38: =IFERROR(IF($H37+1<'General Info and Liability'!$B$15+1,'General Info and Liability'!$D$14/'General Info and Liability'!$B$10*$L38,""),"") | N38: =IFERROR(IF($H37+1<'General Info and Liability'!$B$15+1,'General Info and Liability'!$D$15/'General Info and Liability'!$B$10*$L38,""),"") | Q38: =IFERROR(IF($H38+1>0,'General Info and Liability'!$D$16,""),"") | R38: =IFERROR(IF($H38+1>0,'General Info and Liability'!$B$16,""),"") | S38: =IFERROR(IF($H37+1<'General Info and Liability'!$B$15+1,'General Info and Liability'!$D$17,""),"") | T38: =IFERROR(IF($H37+1<'General Info and Liability'!$B$15+1,'General Info and Liability'!$D$18,""),"") | U38: =IFERROR(IF($H37+1<'General Info and Liability'!$B$15+1,'General Info and Liability'!$D$19,""),"") | V38: =IFERROR(IF($H37+1<'General Info and Liability'!$B$15+1,'General Info and Liability'!$B$14,""),"") | W38: =IFERROR(IF($H37+1<'General Info and Liability'!$B$15+1,'General Info and Liability'!$D$20,""),"")
A39: Trees/Shrubs | F39: 10000 | H39: =IFERROR(IF(H38+1<'General Info and Liability'!$B$15+1,'Property Schedule'!H38+1,""),"") | K39: =IFERROR(IF($H38+1<'General Info and Liability'!$B$15+1,'General Info and Liability'!$B$18/'General Info and Liability'!$B$10*$L39,""),"") | M39: =IFERROR(IF($H38+1<'General Info and Liability'!$B$15+1,'General Info and Liability'!$D$14/'General Info and Liability'!$B$10*$L39,""),"") | N39: =IFERROR(IF($H38+1<'General Info and Liability'!$B$15+1,'General Info and Liability'!$D$15/'General Info and Liability'!$B$10*$L39,""),"") | Q39: =IFERROR(IF($H39+1>0,'General Info and Liability'!$D$16,""),"") | R39: =IFERROR(IF($H39+1>0,'General Info and Liability'!$B$16,""),"") | S39: =IFERROR(IF($H38+1<'General Info and Liability'!$B$15+1,'General Info and Liability'!$D$17,""),"") | T39: =IFERROR(IF($H38+1<'General Info and Liability'!$B$15+1,'General Info and Liability'!$D$18,""),"") | U39: =IFERROR(IF($H38+1<'General Info and Liability'!$B$15+1,'General Info and Liability'!$D$19,""),"") | V39: =IFERROR(IF($H38+1<'General Info and Liability'!$B$15+1,'General Info and Liability'!$B$14,""),"") | W39: =IFERROR(IF($H38+1<'General Info and Liability'!$B$15+1,'General Info and Liability'!$D$20,""),"")
A40: BPP | F40: ='General Info and Liability'!B20 -> 10000 | H40: =IFERROR(IF(H39+1<'General Info and Liability'!$B$15+1,'Property Schedule'!H39+1,""),"") | K40: =IFERROR(IF($H39+1<'General Info and Liability'!$B$15+1,'General Info and Liability'!$B$18/'General Info and Liability'!$B$10*$L40,""),"") | M40: =IFERROR(IF($H39+1<'General Info and Liability'!$B$15+1,'General Info and Liability'!$D$14/'General Info and Liability'!$B$10*$L40,""),"") | N40: =IFERROR(IF($H39+1<'General Info and Liability'!$B$15+1,'General Info and Liability'!$D$15/'General Info and Liability'!$B$10*$L40,""),"") | Q40: =IFERROR(IF($H40+1>0,'General Info and Liability'!$D$16,""),"") | R40: =IFERROR(IF($H40+1>0,'General Info and Liability'!$B$16,""),"") | S40: =IFERROR(IF($H39+1<'General Info and Liability'!$B$15+1,'General Info and Liability'!$D$17,""),"") | T40: =IFERROR(IF($H39+1<'General Info and Liability'!$B$15+1,'General Info and Liability'!$D$18,""),"") | U40: =IFERROR(IF($H39+1<'General Info and Liability'!$B$15+1,'General Info and Liability'!$D$19,""),"") | V40: =IFERROR(IF($H39+1<'General Info and Liability'!$B$15+1,'General Info and Liability'!$B$14,""),"") | W40: =IFERROR(IF($H39+1<'General Info and Liability'!$B$15+1,'General Info and Liability'!$D$20,""),"")
...

Sheet Policy and Cert Info
A1: Include? | B1: Policy Type | C1: Eff date | D1: Base Premium | E1: Issuing Loc | F1: Bill Type | G1: Profit Center | H1: Issuing Co | I1: Premium Payable | J1: Prefill | K1: Pr/Br Comission | L1: Servicing/CSR | M1: Category | N1: Limits
A2: Yes | B2: CPKG/GLIA | C2: 44562 | E2: CA | F2: Agency | G2: HOUS | H2: Accelerant | I2: Arden | J2: 1/2 GL | K2: Greg Meyers | L2: Megan Fitzgerald | M2: Condo Habitational | N2: Aggregate: 2M, Product: 2M, Personal: 1M, Occurrence: 1M, Damage: 100k, Medical: 5k
A3: Yes | B3: CPKG/BAUT | C3: 44562 | E3: CA | F3: Agency | G3: HOUS | H3: Accelerant | I3: Arden | J3: Business Auto | K3: Greg Meyers | L3: Megan Fitzgerald | M3: Condo Habitational | N3: 1m Auto
A4: Yes | B4: CPKG/PROP | C4: 44562 | D4: 20621 | E4: CA | F4: Agency | G4: HOUS | H4: Accelerant | I4: Arden | J4: Property | K4: Greg Meyers | L4: Megan Fitzgerald | M4: Condo Habitational | N4: $25,860,710 / 10k ded
A5: Yes | B5: WC | C5: 44562 | D5: 355 | E5: CA | F5: Direct | G5: HOUS | H5: PMA | I5: CAIS | J5: Work Comp | K5: Greg Meyers | L5: Megan Fitzgerald | M5: Condo Habitational | N5: 1M
A6: Yes | B6: Crime | C6: 44562 | D6: 357 | E6: CA | F6: Direct | G6: HOUS | H6: PMA | I6: CAIS | J6: Crime | K6: Greg Meyers | L6: Megan Fitzgerald | M6: Condo Habitational | N6: Employee Dishonesty: 525k/1k ded, Computer and Funds Fraud: 525k/1k ded
A7: Yes | B7: D&O | C7: 44562 | D7: 1216 | E7: CA | F7: Agency | G7: HOUS | H7: Philadelphia | I7: Gigins | J7: N/A | K7: Greg Meyers | L7: Megan Fitzgerald | M7: Condo Habitational | N7: 1M/1k ded
A8: Yes | B8: Umbrella | C8: 44562 | D8: 681 | E8: CA | F8: Agency | G8: HOUS | H8: Firemans Fund | I8: Trivedi | J8: Umbrella | K8: Greg Meyers | L8: Megan Fitzgerald | M8: Condo Habitational | N8: 2M
A11: Description of Operations
A12: HOA consists of 71 units. Located in Pleasanton, CA 94588. Management Company is Additionally Insured on the General Liability, D&O Liability, and Fidelity Bond. See 2nd page of certificate of insurance for further coverage information.
A13: Single Entity Coverage (Walls In, excluding Improvements and Betterments)
A14: Coverage Includes: Wind/Hail Equipment Breakdown Building Ordinance or Law A+B+C Inflation Guard and/or limits are reviewed yearly to ensure 100% Replacement Cost Severability of Interest / Separation of Insureds Computer Fraud & Funds Transfer Fraud Waiver of Rights of Recovery No Co-Insurance D&O is a Claims-Made Policy Hired and Non-Owned Auto Liability

Sheet LOOKUPS
A1: Yes/No | B1: Association Type | C1: Insuring Agreement | D1: Valuation Type | E1: Smoke Detectors | F1: Construction Type | G1: Roof Type | H1: GL Limits | I1: Parking Type
A2: NO | B2: PUD | C2: Bare Walls | D2: Replacement Cost | E2: Battery | F2: Frame | G2: Tile | H2: 1,000,000/2,000,000 | I2: Habitational over Garage
A3: YES | B3: CONDO | C3: Single Entity | D3: Extended Replacement Cost | E3: Hard-Wired | F3: Joisted Masonry | G3: Comp | H3: 2,000,000/4,000,000 | I3: Detached
B4: Commercial PUD | C4: Single Entity w/ Floor/Wall Covering Exclusion | D4: Guaranteed Replacement Cost | F4: Fire Resistive | G4: Flat | I4: Attached
B5: Commercial CONDO | C5: All-In | F5: Masonry Non-Combustible | G5: Shake | I5: Subterranean
C6: Common Areas Only | I6: Masonry Above-Ground
I7: Partial Subterranean
