Workbook
Name assocfees: [1]Sheet2!$F:$F
Name construction: [1]Sheet2!$E:$E
Name DropDown_AOP_Deductible: #REF!
Name DropDown_BCEG: #REF!
Name DropDown_Business_Income: #REF!
Name DropDown_Coinsurance_Options: #REF!
Name DropDown_ConstGrp2: #REF!
Name DropDown_ConstrGrp1: #REF!
Name DropDown_Construction_Open: #REF!
Name DropDown_County: #REF!
Name DropDown_CoverageType: #REF!
Name DropDown_FormType: #REF!
Name DropDown_Hurricane_Deductible_Type: #REF!
Name Dropdown_Inflation_Guard: #REF!
Name DropDown_Monthly_Limitation_Options: #REF!
Name DropDown_Occupancy: #REF!
Name DropDown_Ordinance_Or_Law: #REF!
Name DropDown_Ordinance_Or_Law_Coverage_Limit: #REF!
Name DropDown_Property_Type_Open: #REF!
Name DropDown_ProtectionClass: #REF!
Name DropDown_Sinkhole_Deductible: #REF!
Name DropDown_Territory: #REF!
Name DropDown_Theft: #REF!
Name DropDown_Units: #REF!
Name DropDown_Wind_Deductible: #REF!
Name DropDown_YesNo: #REF!
Name GAAP_Summary: '[2]DM 1'!#REF!
Name garagetype: [1]Sheet2!$B:$B
Name Grp2ConstructionLookUp: #REF!
Name IRPM_Credit_Options: #REF!
Name ISRTStandardDesignExposureID: #REF!
Name IsRTStandardDesignSpeedID: #REF!
Name IsRTStandardFBCWindSpeedID: #REF!
Name Key.tblFBCequivalentCredits: [3]MAIN!$F$116
Name Key.tblRnfConcrtRoofDeckOnOrAfter2002: [3]MAIN!$F$118
Name Key.tblRnfConcrtRoofDeckPriorTo2002: [3]MAIN!$F$117
Name Key.tblTerrainBOtherRoofDeck: [3]MAIN!$F$119
Name Key.tblTerrainCOtherRoofDeck: [3]MAIN!$F$120
Name Key.tblType_II_III_pre2002: [3]MAIN!$F$121
Name Key.tblType_II_III_Terr_B_post2002: [3]MAIN!$F$122
Name Key.tblType_II_III_Terr_C_post2002: [3]MAIN!$F$123
Name Key.tblTypeI_New_Construction: #REF!
Name Key.tblTypeI_Old_Construction_Other_Roof: #REF!
Name Key.tblTypeI_Old_Construction_RCR: #REF!
Name Key.tblTypeII_New_Construction: #REF!
Name Key.tblTypeII_Old_Construction: #REF!
Name Key.tblTypeIII_New_Construction: #REF!
Name Key.tblTypeIII_Old_Construction: #REF!
Name Lookup_CSPCodes: #REF!
Name lstAgeDwell: '[3]Building Residence'!#REF!
Name lstBCEGgrade: '[3]Building Residence'!$C$188:$C$200
Name lstCovBPct: '[3]Policy Coverage'!#REF!
Name lstCovCPct: '[3]Policy Coverage'!#REF!
Name lstCoverageE: '[3]Policy Coverage'!$B$63:$B$64
Name lstExcludeWindRate: '[3]PolicyInfo & Yes-No'!$B$8:$B$9
Name lstFungiProp: '[3]Optional Coverages'!$B$14:$B$16
Name lstIncidentalOccupancy: '[3]Building Residence'!$B$309:$B$310
Name lstIncreasedDeductibles: '[3]Policy Coverage'!$B$189:$B$201
Name lstIncreasedLossAssessment: '[3]Optional Coverages'!$B$27:$B$28
Name lstnumFireUnits: '[3]Building Residence'!$B$337:$B$346

Sheet Submission Details
A1: Green = Mandatory | B1: White = Optional | C1: Red = Calculation or Not Available | F1: Version: | G1: 2
A3: More than 80% rentals or a YES answer to any of the following questions is NOT eligible for Admitted. If not eligible for Admitted and you'd like Arden to provide a Non-Admitted quote, please complete this Submission Template. | D3: Limits Profile | J3: All States (excpet WA) | P3: WA State Only
A4: Rental % | B4: 0.11 | D4: Insuring Agreement | E4: Single Entity
A5: Is there Aluminum Wiring, Fuses, Federal Pacific Breakers, Stab Lok Breakers, Polybutylene or Galvanized Plumbing? | B5: No | D5: Property Enhancement Option (changes to limits can be made to the right - follow the arrow) | E5: Platinum (Enhanced) | K5: Gold Property Enhancement (BASIC) | L5: Platinum Property Enhancement (ENHANCED) | Q5: Gold Property Enhancement (BASIC) | R5: Platinum Property Enhancement (ENHANCED)
A6: Does the Association have any of the following exposures? | B6: No, the Association does NOT have ANY of these exposures | D6: Building Limit | E6: 9928040
A7: Subsidized housing; Student housing; Assisted living facilities; Timeshare; | D7: Business Personal Property Limit | E7: 25000 | J7: Coverage | K7: Limit | L7: Limit | M7: Update your own limits: | P7: Coverage | Q7: Limit | R7: Limit | S7: Update your own limits:
A8: Armed guard services or dog services; Shooting or archery ranges; | D8: Business Income Limit | E8: 605000 | J8: Accounts Receivable | K8: 5000 | L8: 10000 | P8: Bridges, bulkheads, docks, piers, retaining walls, wharves | Q8: 10000 | R8: 15000
A9: Day care or health facilities; Association owned snow or lake sport facilities; | D9: TIV | J9: Computer & Funds Transfer Fraud | K9: 25000 | L9: 50000 | P9: Community Personal Property in Transit | Q9: 50000 | R9: 75000
A10: Wood shake/shingle roofs; Liquor liability for restaurants or special events; | D10: BOL - Coverage B Limit | E10: 496402 | J10: Computer Equipment, Media and Supplies | K10: 10000 | L10: 25000 | P10: Debris Removal | Q10: 300000 | R10: 325000
A11: Any equestrian activities; Association owned or maintained marinas or boat docks | D11: BOL - Coverage C Limit | E11: 992804 | J11: Crime Reward | K11: 2500 | L11: 5000 | P11: Demolition Costs | Q11: 300000 | R11: 325000
D12: Equipment Breakdown? | E12: Yes | J12: Debris Removal | K12: 150000 | L12: 300000 | P12: Employee Dishonesty, Computer Fraud, Depositors Forgery- A | Q12: 150000 | R12: 175000
A13: General Information | D13: Equipment Breakdown Limit | J13: Electronic Data | K13: 12500 | L13: 25000 | P13: Employee Dishonesty, Computer Fraud, Depositors Forgery- B | Q13: 150000 | R13: 150000
A14: Insured Name | B14: Wolf Creek Lodge Association | D14: EQSL Limit (Available in WA/OR/UT only, Max Cap $10M) | J14: Elevator Collision | K14: 50000 | L14: 100000 | P14: Fine Arts - Per Item | Q14: 15000 | R14: 15000
A15: Agency Name | B15: Socher Insurance Agency | J15: Employee Theft - Stated Value | K15: 25000 | L15: 50000 | P15: Fine Arts - Per Occurrence | Q15: 50000 | R15: 50000
A16: Agency Contact | B16: Candace Rea | J16: Fine Arts | K16: 25000 | L16: 50000 | P16: Fire Department Service Charge | Q16: 10000 | R16: 10000
A17: New or Renewal for Agency | B17: Renewal | D17: Deductibles/Limitations/Exclusions | J17: Fire Department Service Charge | K17: 5000 | L17: 10000 | P17: Fire Extinguisher Recharge | Q17: 1000 | R17: 1000
A18: Has this Association been non-renewed in the last 3 years? | B18: No | D18: GL Limits | E18: $1M / $2M | J18: Fire Extinguisher Recharge | K18: 500 | L18: 1000 | P18: Increased Cost of Construction | Q18: 300000 | R18: 300000
A19: Reason for non-renewal? | D19: GL Deductible ($) | J19: Forgery or Alteration | K19: 25000 | L19: 50000 | P19: Monetary Reward | Q19: 5000 | R19: 5000
A20: If Other, please explain: | D20: Fire Legal Liability | E20: 300000 | J20: Lock Replacement | K20: 500 | L20: 1000 | P20: Natural Outdoor Property | Q20: 20000 | R20: 20000
A21: Renewal Premium | D21: Garage & Parking Liability? | E21: No | J21: Newly Acquired Buildings and Structures | K21: 125000 | L21: 250000 | P21: Newly Acquired Buildings and Structures | Q21: 250000 | R21: 250000
A22: Target Premium | B22: 54182 | D22: Garage & Parking Liability Limit | J22: Newly Acquired Community Personal Property | K22: 125000 | L22: 250000 | P22: Newly Acquired Community Personal Property | Q22: 250000 | R22: 250000
A23: Need by Date | D23: Hired & Non-Owned Auto Liability? | E23: Yes | J23: Newly Constructed Buildings and Structures | K23: 125000 | L23: 250000 | P23: Newly Constructed Buildings and Structures | Q23: 250000 | R23: 250000
A24: Type of Association | B24: Residential Condominium | D24: Hired & Non-Owned Auto Liability Limit | E24: 1000000 | J24: Ordinance or Law - Demolition Cost | K24: 300000 | L24: 500000 | P24: Off Premises Community Personal Property | Q24: 50000 | R24: 50000
A25: Policy Effective Date | B25: 45930 | D25: AOP Deductible | E25: 75000 | J25: Ordinance or Law - Increased Cost of Contruction | K25: 300000 | L25: 500000 | P25: Personal Effects - Per Occurrence | Q25: 15000 | R25: 15000
A26: Type of Policy | B26: Not sure | D26: Water/Sewer/Sprinkler Deductible | J26: Outdoor Property - Bridges, bulkheads, docks, piers, retaining walls, wharves | K26: 5000 | L26: 10000 | P26: Personal Effects - Per Person | Q26: 5000 | R26: 5000
A27: Policy Type | B27: Package | D27: Per Unit: | J27: Outdoor Property - In-ground sprinkler systems and piping | K27: 5000 | L27: 10000 | P27: Pollutant Clean Up and Removal | Q27: 25000 | R27: 25000
A28: Mailing Address | B28: 800 Freeman Lane | D28: Wind & Hail Deductible (%-$) | J28: Outdoor Property - Satellite Dishes and Antennas | K28: 5000 | L28: 10000 | P28: Property of Others - Per Occurrence | Q28: 15000 | R28: 15000
A29: Mailing City | B29: Grass Valley | D29: EQSL Deductible ($) | J29: Outdoor Property - Trees, Shrubs and Plants | K29: 10000 | L29: 20000 | P29: Property of Others - Per Person | Q29: 5000 | R29: 5000
A30: Mailing State | B30: CA | D30: Earthquake Deductible (%) | J30: Personal Effects - Per Occurrence | K30: 7500 | L30: 15000 | P30: Property Removal | Q30: 300000 | R30: 300000
A31: Mailing Zip Code | B31: 95949 | J31: Personal Effects - Per Person | K31: 2500 | L31: 5000 | P31: Removal of Fallen Trees | Q31: 10000 | R31: 10000
D32: Features (if not applicable - leave blank) | F32: Exposure Detail (Count/Square Feet/Acres/Sales/etc.) | J32: Pollutant Clean Up and Removal | K32: 12500 | L32: 25000
A33: Property Management Information | D33: Parking (other than attached garages) | E33: TRUE | F33: Parking Area -sq. ft | G33: 3360 | J33: Preservation of Property | K33: 150000 | L33: 300000
A34: Property Management Company | B34: Board of Directors | D34: Detached Carports/Garage | E34: TRUE | F34: Detached Area -sq. ft | G34: 1400 | J34: Property in Transit | K34: 25000 | L34: 50000
A35: How many years have they managed this property? | D35: Subterranean parking | F35: Subterranean Area -sq. ft | J35: Property of Others - Per Occurrence | K35: 7500 | L35: 15000
A36: How often do they visit this property? | D36: Parks or Playgrounds | F36: Number of playgrounds | J36: Property of Others - Per Person | K36: 2500 | L36: 5000
D37: Swimming Pools | F37: Number of swimming pools | J37: Property Off Premises | K37: 25000 | L37: 50000
A38: Location Information | F38: Max depth | J38: Theft of Money and Securities - Inside/Outside | K38: 7500 | L38: 15000
A39: Location Address | B39: 800 Freeman Lane | F39: Self-Locking/Latching Gate? | J39: Valuable Papers and Records | K39: 12500 | L39: 25000
A40: Location City | B40: Grass Valley | F40: Diving board? | J40: Employee Theft Coverage - Property Managers | K40: 25000 | L40: 75000
A41: Location State | B41: CA | F41: Lifeguards on duty? | J41: Sewer & Drain (Outdoor) | K41: GRC | L41: GRC
...

Sheet Statement of Values
A1: Copy and Paste SOV to this tab OR send separately

Sheet Platinum & Gold Details
C2: Platinum Property Enhancement | H2: Gold Property Enhancement
C4: Coverage | D4: Limit | E4: Premium | H4: Coverage | I4: Limit | J4: Premium
C5: Accounts Receivable | D5: 10000 | E5: Incl. | H5: Accounts Receivable | I5: 5000 | J5: Incl.
C6: Computer & Funds Transfer Fraud | D6: 50000 | E6: Incl. | H6: Computer & Funds Transfer Fraud | I6: 25000 | J6: Incl.
C7: Computer Equipment, Media and Supplies | D7: 25000 | E7: Incl. | H7: Computer Equipment, Media and Supplies | I7: 10000 | J7: Incl.
C8: Crime Reward | D8: 5000 | E8: Incl. | H8: Crime Reward | I8: 2500 | J8: Incl.
C9: Debris Removal | D9: 300000 | E9: Incl. | H9: Debris Removal | I9: 150000 | J9: Incl.
C10: Electronic Data | D10: 25000 | E10: Incl. | H10: Electronic Data | I10: 12500 | J10: Incl.
C11: Elevator Collision | D11: 100000 | E11: Incl. | H11: Elevator Collision | I11: 50000 | J11: Incl.
C12: Employee Theft - Stated Value | D12: 50000 | E12: Incl. | H12: Employee Theft - Stated Value | I12: 25000 | J12: Incl.
C13: Fine Arts | D13: 50000 | E13: Incl. | H13: Fine Arts | I13: 25000 | J13: Incl.
C14: Fire Department Service Charge | D14: 10000 | E14: Incl. | H14: Fire Department Service Charge | I14: 5000 | J14: Incl.
C15: Fire Extinguisher Recharge | D15: 1000 | E15: Incl. | H15: Fire Extinguisher Recharge | I15: 500 | J15: Incl.
C16: Forgery or Alteration | D16: 50000 | E16: Incl. | H16: Forgery or Alteration | I16: 25000 | J16: Incl.
... C37: Employee Theft Coverage - Property Managers | D37: 75000 | E37: Incl. | H37: Employee Theft Coverage - Property Managers | I37: 25000 | J37: Incl.

Sheet Lists
A1: Insuring Agreement | C1: Yes/No | E1: EQSL | G1: Fire Legal | I1: Deductibles | K1: W&H | M1: EQ | O1: Construction Type | Q1: Sprinklers | S1: New/Renewal | U1: Policy Type | W1: Property Enhancement | Y1: Contacts | AA1: Condo Type | AC1: Visits | AE1: Smoke | AG1: Fire | AI1: Managed | AK1: Non-Renewal
A2: All-In | C2: Yes | E2: 500000 | G2: 100000 | I2: 2500 | K2: 0.01 | M2: 0.05 | O2: Frame | Q2: None | S2: New | U2: Package | W2: Gold (Basic) | AA2: Residential Condominium | AC2: Daily | AE2: Battery | AG2: Local | AI2: Less than 1 | AK2: Claims
A3: Single Entity | C3: No | E3: 1000000 | G3: 300000 | I3: 5000 | K3: 0.02 | M3: 0.1 | O3: Joisted Masonry | Q3: 1% to 25% | S3: Renewal | U3: Property only | W3: Platinum (Enhanced) | AA3: Mixed Assoc.- Condos & SFRs | AC3: Weekly | AE3: Hard-Wired | AG3: Central Station | AI3: 1 to 5 | AK3: Brush
A4: Bare Walls | C4: n/a | E4: 2000000 | G4: 1000000 | I4: 10000 | K4: 0.03 | M4: 0.15 | O4: Non-Combustible | Q4: 26% to 50% | U4: GL only | AA4: Mixed Assoc. - Residential & Commercial | AC4: Monthly | AE4: None | AG4: None | AI4: 6 to 10 | AK4: Loss Control
A5: Floors/Ceilings/Walls Excluded | I5: 15000 | K5: 0.04 | O5: Masonry Non-Combustible | Q5: 51% to 100% | AA5: 55+ \Active\ Community | AC5: Quarterly | AI5: More than 10 | AK5: Other
C6: Yes/No | E6: Per Unit | I6: 20000 | K6: 0.05 | O6: Fire Resistive | AC6: Semi-Annually
C7: Yes | E7: AOP | I7: 25000 | K7: 5000 | O7: Modified Fire Resistive | AC7: Annually
C8: No, the Association does NOT have ANY of these exposures | E8: Water/Sewer/Sprinkler | I8: 50000 | K8: 20000 | O8: Brick Veneer | U8: Type of Policy
C9: n/a | I9: 75000 | K9: 50000 | U9: Admitted
A10: =TODAY() -> 45980 | E10: GL Limits | I10: 100000 | K10: 75000 | U10: Surplus Lines
C11: Yes/No | E11: $1M / $2M | K11: 100000 | O11: EQSL | U11: Not sure
C12: Liability | E12: $2M / $4M | I12: 2500 | O12: 25000
C13: Fire | I13: 5000 | O13: 50000
C14: Water | E14: GL Deductible ($) | I14: 10000 | O14: 75000
C15: Wind/Hail | E15: 5000 | I15: 25000
C16: Crime/Vandalism | E16: 10000 | I16: 50000
C17: Other | E17: 15000 | I17: 75000
E18: 25000
C19: Completed/Phasing | E19: 50000
C20: Completed
C21: Phasing
C23: Sprinklers
C24: Entire building
C25: Common areas only
C26: Garage only
C27: Units only
C29: TRUE
C30: FALSE

Sheet AS Template
C3: Risk Characteristic | D3: Detail | L3: COMPLETE INORMATION FOR ALL THAT APPLY
C4: Control Number | L4: Feature | M4: Count | N4: Square Footage (if applicable) | O4: Acres (if applicable)
C5: Prior Policy Number | L5: Parks or Playgrounds | M5: ='Submission Details'!F36 -> Number of playgrounds
C6: Insured Name | D6: ='Submission Details'!B14 -> Wolf Creek Lodge Association | L6: Swimming Pools - NOC | M6: ='Submission Details'!F37 -> Number of swimming pools
C7: Broker Name | D7: ='Submission Details'!B15 -> Socher Insurance Agency | L7: Halls - Other than Not-For-Profit
C8: Property Manager Name | D8: ='Submission Details'!B34 -> Board of Directors | L8: Parking - private | N8: ='Submission Details'!F33 -> Parking Area -sq. ft
C9: Entry Date | D9: =TODAY() -> 45980 | L9: Fitness Center - no attendant | N9: ='Submission Details'!F52 -> Commercial total area sq. ft
C10: Transaction Effective Date | D10: ='Submission Details'!B25 -> 45930 | L10: Lake or Pond | O10: ='Submission Details'!#REF! -> #REF!
C11: Policy Effective Date | D11: =D10 -> 45930 | L11: Condominiums - commercial - bank or mercantile, manufacturing or office (association risk only) | N11: ='Submission Details'!#REF! -> #REF!
C12: Policy Expiration Date | D12: =DATE(YEAR(D11)+1, MONTH(D11), DAY(D11)) -> 46295 | L12: Private Streets, Roads, Highways or Bridges that belong to a Community Association-Existence and Maintenance Hazard only
C13: Location Address | D13: ='Submission Details'!B39 -> 800 Freeman Lane | L13: Halls - Not-For-Profit only | N13: ='Submission Details'!F48 -> Lakes or ponds Max depth
C14: Location City | D14: ='Submission Details'!B40 -> Grass Valley
C15: Location County
C16: Location State | D16: ='Submission Details'!B41 -> CA
C17: Location Zip Code | D17: ='Submission Details'!B42 -> 95949
C18: Valuation Type
C19: Insuring Agreement | D19: ='Submission Details'!E4 -> Single Entity
C20: Building Limit | D20: ='Submission Details'!E6 -> 9928040
C21: Business Personal Property Limit | D21: ='Submission Details'!E7 -> 25000
C22: Business Income Limit | D22: ='Submission Details'!E8 -> 605000
C23: TIV | D23: =SUM(D20:D22) -> 10558040
C24: BOL - Coverage B Limit | D24: ='Submission Details'!E10 -> 496402
C25: BOL - Coverage C Limit | D25: ='Submission Details'!E11 -> 992804
C26: Equipment Breakdown Limit | D26: =IF(D23<100000000, D23, 1000000) -> 10558040
C27: EQSL Limit | D27: ='Submission Details'!E14 -> 0
C28: Earthquake Limit (if applicable) | D28: =IF('Submission Details'!E15>0, 'Submission Details'!E15, "")
C29: GL Occurrence Limit | D29: 1000000
C30: GL Aggregate Limit | D30: =D29*2 -> 2000000
C31: Fire Legal Liability | D31: ='Submission Details'!E20 -> 300000
C32: Garage Parking Liability | D32: ='Submission Details'!E22 -> 0
C33: Hired & Non-Owned Auto Liability Limit | D33: ='Submission Details'!E24 -> 1000000
C34: AOP Deductible | D34: =IF('Submission Details'!E25>0, 'Submission Details'!E25, "") -> 75000
C35: Water/Sewer/Sprinkler Deductible | D35: =IF('Submission Details'!E26>0, 'Submission Details'!E26, "")
C36: Wind & Hail Deductible ($) | D36: =IF('Submission Details'!E28>0, 'Submission Details'!E28, "")
C37: Wind & Hail Deductible (%) | D37: =IF('Submission Details'!E29>0, 'Submission Details'!E29, "")
C38: Wildfire Deductible ($) | D38: N/A
C39: Wildfire Deductible (%) | D39: N/A
C40: Per Unit Deductible ($) | D40: =IF('Submission Details'!#REF!>0, 'Submission Details'!#REF!, "") -> #REF!
C41: EQSL Deductible | D41: =IF('Submission Details'!E30>0, 'Submission Details'!E30, "")
C42: Earthquake Deductible (if applicable) | D42: =IF('Submission Details'!E31>0, 'Submission Details'!E31, "")
...
